2024-10-03 18:28:40,504 INFO    MainThread:127263 [wandb_setup.py:_flush():77] Current SDK version is 0.17.8
2024-10-03 18:28:40,504 INFO    MainThread:127263 [wandb_setup.py:_flush():77] Configure stats pid to 127263
2024-10-03 18:28:40,504 INFO    MainThread:127263 [wandb_setup.py:_flush():77] Loading settings from /home/geo_llm/.config/wandb/settings
2024-10-03 18:28:40,504 INFO    MainThread:127263 [wandb_setup.py:_flush():77] Loading settings from /home/geo_llm/llama3-finetune/wandb/settings
2024-10-03 18:28:40,505 INFO    MainThread:127263 [wandb_setup.py:_flush():77] Loading settings from environment variables: {}
2024-10-03 18:28:40,505 INFO    MainThread:127263 [wandb_setup.py:_flush():77] Applying setup settings: {'_disable_service': False}
2024-10-03 18:28:40,505 INFO    MainThread:127263 [wandb_setup.py:_flush():77] Inferring run settings from compute environment: {'program_relpath': 'Evaluate_Llama3.py', 'program_abspath': '/home/geo_llm/llama3-finetune/Evaluate_Llama3.py', 'program': '/home/geo_llm/llama3-finetune/Evaluate_Llama3.py'}
2024-10-03 18:28:40,505 INFO    MainThread:127263 [wandb_setup.py:_flush():77] Applying login settings: {}
2024-10-03 18:28:40,505 INFO    MainThread:127263 [wandb_init.py:_log_setup():524] Logging user logs to /home/geo_llm/llama3-finetune/wandb/run-20241003_182840-9bpvcmta/logs/debug.log
2024-10-03 18:28:40,505 INFO    MainThread:127263 [wandb_init.py:_log_setup():525] Logging internal logs to /home/geo_llm/llama3-finetune/wandb/run-20241003_182840-9bpvcmta/logs/debug-internal.log
2024-10-03 18:28:40,505 INFO    MainThread:127263 [wandb_init.py:init():607] calling init triggers
2024-10-03 18:28:40,505 INFO    MainThread:127263 [wandb_init.py:init():614] wandb.init called with sweep_config: {}
config: {}
2024-10-03 18:28:40,505 INFO    MainThread:127263 [wandb_init.py:init():657] starting backend
2024-10-03 18:28:40,506 INFO    MainThread:127263 [wandb_init.py:init():661] setting up manager
2024-10-03 18:28:40,507 INFO    MainThread:127263 [backend.py:_multiprocessing_setup():105] multiprocessing start_methods=fork,spawn,forkserver, using: spawn
2024-10-03 18:28:40,508 INFO    MainThread:127263 [wandb_init.py:init():669] backend started and connected
2024-10-03 18:28:40,509 INFO    MainThread:127263 [wandb_init.py:init():767] updated telemetry
2024-10-03 18:28:40,514 INFO    MainThread:127263 [wandb_init.py:init():800] communicating run to backend with 90.0 second timeout
2024-10-03 18:28:41,023 INFO    MainThread:127263 [wandb_init.py:init():851] starting run threads in backend
2024-10-03 18:28:44,934 WARNING MainThread:127263 [wandb_init.py:init():1232] interrupted
Traceback (most recent call last):
  File "/home/geo_llm/anaconda3/envs/unsloth_env/lib/python3.10/site-packages/wandb/sdk/wandb_init.py", line 1228, in init
    return wi.init()
  File "/home/geo_llm/anaconda3/envs/unsloth_env/lib/python3.10/site-packages/wandb/sdk/wandb_init.py", line 893, in init
    run._on_start()
  File "/home/geo_llm/anaconda3/envs/unsloth_env/lib/python3.10/site-packages/wandb/sdk/wandb_run.py", line 2503, in _on_start
    self._backend.interface.publish_python_packages(working_set())
  File "/home/geo_llm/anaconda3/envs/unsloth_env/lib/python3.10/site-packages/wandb/sdk/interface/interface.py", line 301, in publish_python_packages
    for pkg in working_set:
  File "/home/geo_llm/anaconda3/envs/unsloth_env/lib/python3.10/site-packages/wandb/util.py", line 1887, in working_set
    yield InstalledDistribution(key=d.metadata["Name"], version=d.version)
  File "/home/geo_llm/anaconda3/envs/unsloth_env/lib/python3.10/importlib/metadata/__init__.py", line 627, in version
    return self.metadata['Version']
  File "/home/geo_llm/anaconda3/envs/unsloth_env/lib/python3.10/importlib/metadata/__init__.py", line 605, in metadata
    self.read_text('METADATA')
  File "/home/geo_llm/anaconda3/envs/unsloth_env/lib/python3.10/importlib/metadata/__init__.py", line 927, in read_text
    return self._path.joinpath(filename).read_text(encoding='utf-8')
  File "/home/geo_llm/anaconda3/envs/unsloth_env/lib/python3.10/pathlib.py", line 1134, in read_text
    with self.open(mode='r', encoding=encoding, errors=errors) as f:
  File "/home/geo_llm/anaconda3/envs/unsloth_env/lib/python3.10/pathlib.py", line 1119, in open
    return self._accessor.open(self, mode, buffering, encoding, errors,
  File "/home/geo_llm/anaconda3/envs/unsloth_env/lib/python3.10/codecs.py", line 309, in __init__
    def __init__(self, errors='strict'):
KeyboardInterrupt
2024-10-03 18:28:51,819 WARNING MsgRouterThr:127263 [router.py:message_loop():77] message_loop has been closed
