[34m[1mwandb[39m[22m: [32m[41mERROR[39m[49m artifact 'model-C_eval_loss:epoch_1.0' not found in 'tanghulu/HuMob2024cityD'
Traceback (most recent call last):
  File "/home/geo_llm/anaconda3/envs/unsloth_env/lib/python3.10/site-packages/wandb/apis/normalize.py", line 41, in wrapper
    return func(*args, **kwargs)
  File "/home/geo_llm/anaconda3/envs/unsloth_env/lib/python3.10/site-packages/wandb/apis/public/api.py", line 1034, in artifact
    artifact = wandb.Artifact._from_name(
  File "/home/geo_llm/anaconda3/envs/unsloth_env/lib/python3.10/site-packages/wandb/sdk/artifacts/artifact.py", line 275, in _from_name
    raise ValueError(f"artifact '{name}' not found in '{entity}/{project}'")
ValueError: artifact 'model-C_eval_loss:epoch_1.0' not found in 'tanghulu/HuMob2024cityD'
During handling of the above exception, another exception occurred:
Traceback (most recent call last):
  File "/home/geo_llm/llama3-finetune/HuMob_wandb.py", line 167, in <module>
    artifact = run.use_artifact('tanghulu/HuMob2024cityD/model-C_eval_loss:epoch_1.0', type='model')
  File "/home/geo_llm/anaconda3/envs/unsloth_env/lib/python3.10/site-packages/wandb/sdk/wandb_run.py", line 403, in wrapper_fn
    return func(self, *args, **kwargs)
  File "/home/geo_llm/anaconda3/envs/unsloth_env/lib/python3.10/site-packages/wandb/sdk/wandb_run.py", line 393, in wrapper
    return func(self, *args, **kwargs)
  File "/home/geo_llm/anaconda3/envs/unsloth_env/lib/python3.10/site-packages/wandb/sdk/wandb_run.py", line 3028, in use_artifact
    artifact = public_api.artifact(type=type, name=name)
  File "/home/geo_llm/anaconda3/envs/unsloth_env/lib/python3.10/site-packages/wandb/apis/normalize.py", line 87, in wrapper
    raise CommError(message, err).with_traceback(sys.exc_info()[2])
  File "/home/geo_llm/anaconda3/envs/unsloth_env/lib/python3.10/site-packages/wandb/apis/normalize.py", line 41, in wrapper
    return func(*args, **kwargs)
  File "/home/geo_llm/anaconda3/envs/unsloth_env/lib/python3.10/site-packages/wandb/apis/public/api.py", line 1034, in artifact
    artifact = wandb.Artifact._from_name(
  File "/home/geo_llm/anaconda3/envs/unsloth_env/lib/python3.10/site-packages/wandb/sdk/artifacts/artifact.py", line 275, in _from_name
    raise ValueError(f"artifact '{name}' not found in '{entity}/{project}'")
wandb.errors.CommError: artifact 'model-C_eval_loss:epoch_1.0' not found in 'tanghulu/HuMob2024cityD'