2024-09-15 02:01:53,270 INFO    MainThread:1385933 [wandb_setup.py:_flush():77] Current SDK version is 0.17.8
2024-09-15 02:01:53,270 INFO    MainThread:1385933 [wandb_setup.py:_flush():77] Configure stats pid to 1385933
2024-09-15 02:01:53,271 INFO    MainThread:1385933 [wandb_setup.py:_flush():77] Loading settings from /home/geo_llm/.config/wandb/settings
2024-09-15 02:01:53,271 INFO    MainThread:1385933 [wandb_setup.py:_flush():77] Loading settings from /home/geo_llm/llama3-finetune/wandb/settings
2024-09-15 02:01:53,271 INFO    MainThread:1385933 [wandb_setup.py:_flush():77] Loading settings from environment variables: {}
2024-09-15 02:01:53,271 INFO    MainThread:1385933 [wandb_setup.py:_flush():77] Applying setup settings: {'_disable_service': False}
2024-09-15 02:01:53,271 INFO    MainThread:1385933 [wandb_setup.py:_flush():77] Inferring run settings from compute environment: {'program_relpath': 'main.py', 'program_abspath': '/home/geo_llm/llama3-finetune/main.py', 'program': '/home/geo_llm/llama3-finetune/main.py'}
2024-09-15 02:01:53,271 INFO    MainThread:1385933 [wandb_setup.py:_flush():77] Applying login settings: {}
2024-09-15 02:01:53,271 INFO    MainThread:1385933 [wandb_init.py:_log_setup():524] Logging user logs to /home/geo_llm/llama3-finetune/wandb/run-20240915_020153-3shlcvii/logs/debug.log
2024-09-15 02:01:53,271 INFO    MainThread:1385933 [wandb_init.py:_log_setup():525] Logging internal logs to /home/geo_llm/llama3-finetune/wandb/run-20240915_020153-3shlcvii/logs/debug-internal.log
2024-09-15 02:01:53,271 INFO    MainThread:1385933 [wandb_init.py:init():607] calling init triggers
2024-09-15 02:01:53,271 INFO    MainThread:1385933 [wandb_init.py:init():614] wandb.init called with sweep_config: {}
config: {}
2024-09-15 02:01:53,272 INFO    MainThread:1385933 [wandb_init.py:init():657] starting backend
2024-09-15 02:01:53,272 INFO    MainThread:1385933 [wandb_init.py:init():661] setting up manager
2024-09-15 02:01:53,275 INFO    MainThread:1385933 [backend.py:_multiprocessing_setup():105] multiprocessing start_methods=fork,spawn,forkserver, using: spawn
2024-09-15 02:01:53,276 INFO    MainThread:1385933 [wandb_init.py:init():669] backend started and connected
2024-09-15 02:01:53,279 INFO    MainThread:1385933 [wandb_init.py:init():767] updated telemetry
2024-09-15 02:01:53,286 INFO    MainThread:1385933 [wandb_init.py:init():800] communicating run to backend with 90.0 second timeout
2024-09-15 02:01:53,726 INFO    MainThread:1385933 [wandb_init.py:init():851] starting run threads in backend
2024-09-15 02:01:57,369 INFO    MainThread:1385933 [wandb_run.py:_console_start():2463] atexit reg
2024-09-15 02:01:57,369 INFO    MainThread:1385933 [wandb_run.py:_redirect():2309] redirect: wrap_raw
2024-09-15 02:01:57,369 INFO    MainThread:1385933 [wandb_run.py:_redirect():2374] Wrapping output streams.
2024-09-15 02:01:57,369 INFO    MainThread:1385933 [wandb_run.py:_redirect():2399] Redirects installed.
2024-09-15 02:01:57,371 INFO    MainThread:1385933 [wandb_init.py:init():894] run started, returning control to user process
2024-09-16 08:28:31,831 INFO    MainThread:1385933 [wandb_run.py:_finish():2160] finishing run tanghulu/Inference/3shlcvii
2024-09-16 08:28:31,833 INFO    MainThread:1385933 [wandb_run.py:_atexit_cleanup():2424] got exitcode: 0
2024-09-16 08:28:31,833 INFO    MainThread:1385933 [wandb_run.py:_restore():2406] restore
2024-09-16 08:28:31,833 INFO    MainThread:1385933 [wandb_run.py:_restore():2412] restore done
2024-09-16 08:28:31,833 INFO    MainThread:1385933 [wandb_run.py:_on_finish():2677] communicating current version
2024-09-16 08:28:35,453 INFO    MainThread:1385933 [wandb_run.py:_on_finish():2686] got version response upgrade_message: "wandb version 0.18.0 is available!  To upgrade, please run:\n $ pip install wandb --upgrade"

2024-09-16 08:28:37,624 INFO    MainThread:1385933 [wandb_run.py:_restore():2406] restore
2024-09-16 08:28:37,624 INFO    MainThread:1385933 [wandb_run.py:_restore():2412] restore done
2024-09-16 08:28:37,624 ERROR   MainThread:1385933 [wandb_run.py:_atexit_cleanup():2445] Problem finishing run
Traceback (most recent call last):
  File "/home/geo_llm/anaconda3/envs/unsloth_env/lib/python3.10/site-packages/wandb/sdk/wandb_run.py", line 2436, in _atexit_cleanup
    self._on_finish()
  File "/home/geo_llm/anaconda3/envs/unsloth_env/lib/python3.10/site-packages/wandb/sdk/wandb_run.py", line 2699, in _on_finish
    _ = exit_handle.wait(timeout=-1, on_progress=self._on_progress_exit)
  File "/home/geo_llm/anaconda3/envs/unsloth_env/lib/python3.10/site-packages/wandb/sdk/lib/mailbox.py", line 303, in wait
    on_progress(progress_handle)
  File "/home/geo_llm/anaconda3/envs/unsloth_env/lib/python3.10/site-packages/wandb/sdk/wandb_run.py", line 2662, in _on_progress_exit
    self._footer_file_pusher_status_info(
  File "/home/geo_llm/anaconda3/envs/unsloth_env/lib/python3.10/site-packages/wandb/sdk/wandb_run.py", line 3892, in _footer_file_pusher_status_info
    Run._footer_single_run_file_pusher_status_info(
  File "/home/geo_llm/anaconda3/envs/unsloth_env/lib/python3.10/site-packages/wandb/sdk/wandb_run.py", line 3939, in _footer_single_run_file_pusher_status_info
    printer.progress_update(line, stats.uploaded_bytes / stats.total_bytes)
  File "/home/geo_llm/anaconda3/envs/unsloth_env/lib/python3.10/site-packages/wandb/sdk/lib/printer.py", line 172, in progress_update
    wandb.termlog(f"{next(self._progress)} {text}", newline=False)
  File "/home/geo_llm/anaconda3/envs/unsloth_env/lib/python3.10/site-packages/wandb/errors/term.py", line 42, in termlog
    _log(
  File "/home/geo_llm/anaconda3/envs/unsloth_env/lib/python3.10/site-packages/wandb/errors/term.py", line 103, in _log
    click.echo(line, file=sys.stderr, nl=newline)
  File "/home/geo_llm/anaconda3/envs/unsloth_env/lib/python3.10/site-packages/click/utils.py", line 318, in echo
    file.write(out)  # type: ignore
OSError: [Errno 5] Input/output error
